2025-01-04 14:48:23 - Error - ERROR - [main.py:127] - ValueError: ValueError - User: UNKNOWN
2025-01-04 15:15:46 - Error - ERROR - [main.py:139] - Unhandled Exception: LineBalanceDAO.is_line_balance_exists() missing 1 required positional argument: 'layout_id' - User: UNKNOWN
2025-01-04 15:17:05 - Error - ERROR - [main.py:148] - TypeError: LineBalanceDAO.is_line_balance_exists() missing 1 required positional argument: 'layout_id' - User: UNKNOWN
2025-01-04 15:17:13 - Error - ERROR - [main.py:148] - TypeError: LineBalanceDAO.is_line_balance_exists() missing 1 required positional argument: 'layout_id' - User: UNKNOWN
2025-01-04 15:17:24 - Error - ERROR - [main.py:148] - TypeError: LineBalanceDAO.is_line_balance_exists() missing 1 required positional argument: 'layout_id' - User: UNKNOWN
2025-01-04 15:22:18 - Error - ERROR - [main.py:148] - TypeError: LineBalanceDAO.is_line_balance_exists() missing 1 required positional argument: 'layout_id' - User: UNKNOWN
2025-01-04 15:24:00 - Error - ERROR - [main.py:148] - TypeError: LineBalanceDAO.is_line_balance_exists() missing 1 required positional argument: 'layout_id' - User: UNKNOWN
2025-01-04 15:24:28 - Error - ERROR - [main.py:148] - TypeError: LineBalanceDAO.is_line_balance_exists() missing 1 required positional argument: 'layout_id' - User: UNKNOWN
2025-01-04 15:24:36 - Error - ERROR - [main.py:148] - TypeError: LineBalanceDAO.is_line_balance_exists() missing 1 required positional argument: 'layout_id' - User: UNKNOWN
2025-01-04 15:24:37 - Error - ERROR - [main.py:148] - TypeError: LineBalanceDAO.is_line_balance_exists() missing 1 required positional argument: 'layout_id' - User: UNKNOWN
2025-01-04 15:26:50 - Error - ERROR - [main.py:108] - SQLAlchemy Error: Class 'builtins.str' is not mapped - User: UNKNOWN
2025-01-04 17:08:39 - Error - ERROR - [main.py:139] - Unhandled Exception: 'Query' object has no attribute 'last' - User: UNKNOWN
2025-01-04 21:32:34 - Error - ERROR - [main.py:108] - SQLAlchemy Error: Entity namespace for "ct_cycle_time_takes" has no property "layout_id" - User: UNKNOWN
2025-01-04 21:33:24 - Error - ERROR - [main.py:108] - SQLAlchemy Error: Entity namespace for "ct_cycle_time_takes" has no property "layout_id" - User: UNKNOWN
2025-01-04 21:50:13 - Error - ERROR - [main.py:96] - HTTPException: Work plans for date 2025-01-04 not found (status: 404) - User: UNKNOWN
2025-01-04 22:22:56 - Error - ERROR - [main.py:139] - Unhandled Exception: Not enough segments - User: UNKNOWN
2025-01-04 22:22:56 - Error - ERROR - [main.py:139] - Unhandled Exception: Not enough segments - User: UNKNOWN
2025-01-04 22:22:58 - Error - ERROR - [main.py:139] - Unhandled Exception: Not enough segments - User: UNKNOWN
2025-01-04 22:23:06 - Error - ERROR - [main.py:139] - Unhandled Exception: Not enough segments - User: UNKNOWN
2025-01-04 22:23:06 - Error - ERROR - [main.py:139] - Unhandled Exception: Not enough segments - User: UNKNOWN
2025-01-04 22:23:07 - Error - ERROR - [main.py:139] - Unhandled Exception: Not enough segments - User: UNKNOWN
2025-01-04 22:23:07 - Error - ERROR - [main.py:139] - Unhandled Exception: Not enough segments - User: UNKNOWN
2025-01-04 22:24:22 - Error - ERROR - [main.py:139] - Unhandled Exception: Not enough segments - User: UNKNOWN
2025-01-04 22:24:22 - Error - ERROR - [main.py:139] - Unhandled Exception: Not enough segments - User: UNKNOWN
2025-01-04 22:24:23 - Error - ERROR - [main.py:139] - Unhandled Exception: Not enough segments - User: UNKNOWN
2025-01-04 22:24:23 - Error - ERROR - [main.py:139] - Unhandled Exception: Not enough segments - User: UNKNOWN
2025-01-04 22:25:06 - Error - ERROR - [main.py:139] - Unhandled Exception: Not enough segments - User: UNKNOWN
2025-01-04 22:25:06 - Error - ERROR - [main.py:139] - Unhandled Exception: Not enough segments - User: UNKNOWN
2025-01-04 22:25:07 - Error - ERROR - [main.py:139] - Unhandled Exception: Not enough segments - User: UNKNOWN
2025-01-04 22:25:07 - Error - ERROR - [main.py:139] - Unhandled Exception: Not enough segments - User: UNKNOWN
2025-01-04 22:25:24 - Error - ERROR - [main.py:139] - Unhandled Exception: Not enough segments - User: UNKNOWN
2025-01-04 22:25:24 - Error - ERROR - [main.py:139] - Unhandled Exception: Not enough segments - User: UNKNOWN
2025-01-04 22:25:25 - Error - ERROR - [main.py:139] - Unhandled Exception: Not enough segments - User: UNKNOWN
2025-01-04 22:25:25 - Error - ERROR - [main.py:139] - Unhandled Exception: Not enough segments - User: UNKNOWN
2025-01-04 22:25:25 - Error - ERROR - [main.py:139] - Unhandled Exception: Not enough segments - User: UNKNOWN
2025-01-04 22:25:25 - Error - ERROR - [main.py:139] - Unhandled Exception: Not enough segments - User: UNKNOWN
2025-01-04 22:25:26 - Error - ERROR - [main.py:139] - Unhandled Exception: Not enough segments - User: UNKNOWN
2025-01-04 22:25:29 - Error - ERROR - [main.py:139] - Unhandled Exception: Not enough segments - User: UNKNOWN
2025-01-04 22:25:36 - Error - ERROR - [main.py:139] - Unhandled Exception: Not enough segments - User: UNKNOWN
2025-01-04 22:25:36 - Error - ERROR - [main.py:139] - Unhandled Exception: Not enough segments - User: UNKNOWN
2025-01-04 22:25:36 - Error - ERROR - [main.py:139] - Unhandled Exception: Not enough segments - User: UNKNOWN
2025-01-04 22:25:36 - Error - ERROR - [main.py:139] - Unhandled Exception: Not enough segments - User: UNKNOWN
2025-01-04 22:25:38 - Error - ERROR - [main.py:139] - Unhandled Exception: Not enough segments - User: UNKNOWN
2025-01-04 22:25:56 - Error - ERROR - [main.py:139] - Unhandled Exception: Not enough segments - User: UNKNOWN
2025-01-04 22:25:56 - Error - ERROR - [main.py:139] - Unhandled Exception: Not enough segments - User: UNKNOWN
2025-01-04 22:25:56 - Error - ERROR - [main.py:139] - Unhandled Exception: Not enough segments - User: UNKNOWN
2025-01-04 22:25:56 - Error - ERROR - [main.py:139] - Unhandled Exception: Not enough segments - User: UNKNOWN
2025-01-04 22:25:57 - Error - ERROR - [main.py:139] - Unhandled Exception: Not enough segments - User: UNKNOWN
2025-01-04 22:25:57 - Error - ERROR - [main.py:139] - Unhandled Exception: Not enough segments - User: UNKNOWN
2025-01-04 22:27:13 - Error - ERROR - [main.py:139] - Unhandled Exception: Not enough segments - User: UNKNOWN
2025-01-04 22:27:44 - Error - ERROR - [main.py:139] - Unhandled Exception: Not enough segments - User: UNKNOWN
2025-01-04 22:27:44 - Error - ERROR - [main.py:139] - Unhandled Exception: Not enough segments - User: UNKNOWN
2025-01-04 22:27:44 - Error - ERROR - [main.py:139] - Unhandled Exception: Not enough segments - User: UNKNOWN
2025-01-04 22:27:44 - Error - ERROR - [main.py:139] - Unhandled Exception: Not enough segments - User: UNKNOWN
2025-01-04 22:27:53 - Error - ERROR - [main.py:139] - Unhandled Exception: Not enough segments - User: UNKNOWN
2025-01-04 22:27:53 - Error - ERROR - [main.py:139] - Unhandled Exception: Not enough segments - User: UNKNOWN
2025-01-04 22:27:54 - Error - ERROR - [main.py:139] - Unhandled Exception: Not enough segments - User: UNKNOWN
2025-01-04 22:27:54 - Error - ERROR - [main.py:139] - Unhandled Exception: Not enough segments - User: UNKNOWN
2025-01-04 22:28:25 - Error - ERROR - [main.py:139] - Unhandled Exception: Not enough segments - User: UNKNOWN
2025-01-04 22:28:25 - Error - ERROR - [main.py:139] - Unhandled Exception: Not enough segments - User: UNKNOWN
2025-01-04 22:35:18 - Error - ERROR - [main.py:141] - Unhandled Exception: Not enough segments - User: UNKNOWN
2025-01-04 22:38:30 - Error - ERROR - [main.py:141] - Unhandled Exception: Not enough segments - User: UNKNOWN
2025-01-04 22:46:03 - Error - ERROR - [main.py:98] - HTTPException: Cycle times for take Zkr7KWi1PWtz568 not found (status: 404) - User: UNKNOWN
2025-01-04 22:46:50 - Error - ERROR - [main.py:98] - HTTPException: Cycle times for take Zkr7KWi1PWtz568 not found (status: 404) - User: UNKNOWN
2025-01-04 22:46:50 - Error - ERROR - [main.py:98] - HTTPException: Cycle times for take 85heqeSUObPgSod not found (status: 404) - User: UNKNOWN
2025-01-04 22:46:51 - Error - ERROR - [main.py:98] - HTTPException: Cycle times for take Zkr7KWi1PWtz568 not found (status: 404) - User: UNKNOWN
2025-01-04 22:46:51 - Error - ERROR - [main.py:98] - HTTPException: Cycle times for take 85heqeSUObPgSod not found (status: 404) - User: UNKNOWN
2025-01-04 22:46:52 - Error - ERROR - [main.py:98] - HTTPException: Cycle times for take Zkr7KWi1PWtz568 not found (status: 404) - User: UNKNOWN
2025-01-04 22:46:52 - Error - ERROR - [main.py:98] - HTTPException: Cycle times for take 85heqeSUObPgSod not found (status: 404) - User: UNKNOWN
2025-01-04 22:46:55 - Error - ERROR - [main.py:98] - HTTPException: Cycle times for take Zkr7KWi1PWtz568 not found (status: 404) - User: UNKNOWN
2025-01-04 22:47:00 - Error - ERROR - [main.py:98] - HTTPException: Cycle times for take Zkr7KWi1PWtz568 not found (status: 404) - User: UNKNOWN
2025-01-04 22:47:09 - Error - ERROR - [main.py:98] - HTTPException: Cycle times for take Zkr7KWi1PWtz568 not found (status: 404) - User: UNKNOWN
2025-01-04 22:48:04 - Error - ERROR - [main.py:98] - HTTPException: Cycle times for take Zkr7KWi1PWtz568 not found (status: 404) - User: UNKNOWN
2025-01-04 22:48:09 - Error - ERROR - [main.py:98] - HTTPException: Cycle times for take Zkr7KWi1PWtz568 not found (status: 404) - User: UNKNOWN
2025-01-04 22:48:13 - Error - ERROR - [main.py:98] - HTTPException: Cycle times for take Zkr7KWi1PWtz568 not found (status: 404) - User: UNKNOWN
2025-01-04 22:48:15 - Error - ERROR - [main.py:98] - HTTPException: Cycle times for take Zkr7KWi1PWtz568 not found (status: 404) - User: UNKNOWN
2025-01-04 22:49:32 - Error - ERROR - [main.py:150] - TypeError: exceptions must derive from BaseException - User: UNKNOWN
2025-01-04 22:51:32 - Error - ERROR - [main.py:150] - TypeError: exceptions must derive from BaseException - User: UNKNOWN
2025-01-04 22:52:29 - Error - ERROR - [main.py:150] - TypeError: exceptions must derive from BaseException - User: UNKNOWN
2025-01-04 22:54:00 - Error - ERROR - [main.py:150] - TypeError: exceptions must derive from BaseException - User: UNKNOWN
2025-01-04 22:54:33 - Error - ERROR - [main.py:150] - TypeError: exceptions must derive from BaseException - User: UNKNOWN
